







































Epoch: 0001 | Iter: 3750 | G Loss: 0.89 | D Loss: 1.20 | MI: 1.48 | Real Acc: 75.00% | Fake Acc: 600.00%: 100%|█| 3750/3750 [01:20<00:00, 46.63it/







































Epoch: 0002 | Iter: 3750 | G Loss: 0.91 | D Loss: 1.18 | MI: 1.54 | Real Acc: 68.75% | Fake Acc: 1300.00%: 100%|█| 3750/3750 [01:20<00:00, 46.84it



































Epoch: 0003 | Iter: 3007 | G Loss: 0.88 | D Loss: 1.15 | MI: 1.60 | Real Acc: 81.25% | Fake Acc: 1200.00%:  80%|▊| 3007/3750 [01:11<00:17, 41.77it
Traceback (most recent call last):
  File "dd.py", line 270, in <module>
  File "dd.py", line 244, in main
    pgs.set_description(f'Epoch: {epoch + 1:04d} | Iter: {i + 1:04d} | G Loss: {G_loss.item():.2f} | D Loss: {D_loss.item():.2f} | MI: {MI.item():.2f} | Real Acc: {(torch.round(real_logits) == real_label).sum() / real_label.shape[0] * 100:.2f}% | Fake Acc: {(torch.round(fake_logits) == fake_label).sum() / fake_label.shape[0] * 100:.2f}%')
RuntimeError: CUDA error: an illegal memory access was encountered
CUDA kernel errors might be asynchronously reported at some other API call,so the stacktrace below might be incorrect.
For debugging consider passing CUDA_LAUNCH_BLOCKING=1.